Workbook

Sheet stage10_integration
A1: STAGE 10 — INTEGRATED STUDY: UK · DE · CN INDUSTRIAL ELECTRICITY PRICES (front page + final QC)
A2: The study in one page: what industry pays, why, and what policy can do. Ten stages, one workbook. Real-2025 USD unless noted (house rule 1/D1: nominal local × Fed H.10 annual-avg FX × US CPI-U; VAT excluded). This front page is formula-linked to the underlying stages; the consistency panel (Section C) and integrity panel (Section D) are live gates. CN price series: 含税 (incl VAT) as published — Q84; de-VAT memo stage6 r189–191.
A4: A. THE HEADLINE — modelled cost stack & system cost, 2025 (real-2025 USD/MWh; statutory components, SUPPLY MARGIN EXCLUDED; source stage6_decomp T3; observed comparators row 9)
B5: Country / archetype | C5: Modelled stack E1 (unrelieved) | D5: Modelled stack E2 (relieved) | E5: System cost (modelled) | F5: Relief channel
B6: United Kingdom (large) | C6: =stage6_decomp!D148 | D6: =stage6_decomp!D149 | E6: =stage6_decomp!G148 | F6: other bill-payers (cross-subsidy)
B7: Germany (large) | C7: =stage6_decomp!D152 | D7: =stage6_decomp!D153 | E7: =stage6_decomp!G152 | F7: taxpayer (EEG on budget + Stromsteuer); §19 network rebate → other users. KTF network subsidy from 2026
B8: China (large) | C8: =stage6_decomp!D156 | F8: reverse: industry → residential (on-bill only; system cost unquantified, ≤ bill)
B9: OBSERVED 2025 (band averages, context): UK QEP Extra Large excl CCL | C9: =timeseries!S78 | D9: DE Eurostat IF | E9: =timeseries!S86 | F9: UK obs − modelled E1 = supply margin (Q30 gate: UK FAIL 2025 — exhibit, not error) | G9: =stage6_decomp!T121
B10: READING: UK and German MODELLED SYSTEM COST is similar (UK $207/$213 vs DE $211/$231 large/medium) — the UK–DE difference is WHO PAYS (policy/gen-capital recovery on UK bills), not the size of the stack. China's ~$87 is an ON-BILL price (different basis; its unquantified system cost ≤ bill). Observed 2025 bills sit ~$80/MWh above the UK modelled stack (supply margin, row 9). See Section B (Stages 6, 9).
A11: B. STAGE-BY-STAGE SYNTHESIS
B12: Stage / building block | C12: Headline finding | D12: Key metric | F12: Source tab
B13: 1-3 Method & anchors | C13: House rule fixes real-2025 USD pipeline (H.10 FX, US CPI, VAT excluded); 10 golden anchors reproduce as permanent regression tests. | E13: GN reproduce ✓ | F13: golden_numbers, fx_deflator, assumptions
B14: 4 Price assembly | C14: Nominal-local industrial series (UK day-ahead/forward; DE Phelix; CN catalogue+market) converted to a common real-2025 USD basis. | E14: see timeseries | F14: stage4_uk/de/cn, timeseries, lcoe, cn_td
B15: 5 Output & intensity | C15: Energy-intensive output paths diverge (UK severe contraction: aluminium index 16, steel 41 by 2024; DE material post-2021 contraction: EI aggregate ~81, aluminium 55; CN long-run expansion, post-2021 plateau/decline in cement/steel/glass) — shown with mandatory causal caution (price ≠ sole cause). | E15: causal caution | F15: stage5_output
B16: 6 Decomposition | C16: Five-bucket cost stack + WHO-PAYS vs WHAT-IT-COSTS: relief relocates cost (UK→bills, DE→taxpayer, CN reverse). All reconciliation gates PASS (internal, by construction — Q46; independent checks: golden numbers + observed-vs-modelled gates, Q30). | E16: 151/151 (by construction) | F16: stage6_decomp, carbon
B17: 7 Network drivers | C17: Network charges the fastest-rising bucket; UK residual +94% (26/27); DE outturn already above BDEW path; CN wire held flat, cost surfaces in system fee. | E17: UK net +60% 25→26 | F17: stage7_network
B18: 8 Supply / tech / flex | C18: None of North Sea gas, nuclear, geothermal or flexibility is a NEAR-TERM price lever (UK a gas price-taker; nuclear 10+yr & high FOAK; geothermal pre-commercial; flex indirect). | E18: not near-term | F18: north_sea_og, nuclear_global, geothermal_uk, flexibility_network
B19: 9 Policy options | C19: Balanced options: cost-SHIFTING (exemptions) vs cost-REDUCING (structural). UK converging on the German taxpayer model (BICS: Exchequer + energy-system funded, final split at Budget 2026; CPS abolition 2028). | E19: 6 levers, tagged | F19: stage9_policy
B20: 10 Integration & QC | C20: This front page + full-workbook QC: 0 formula errors, golden numbers reproduce, signed stages preserved, source/decision/qc integrity, cross-stage consistency. | E20: see C & D | F20: stage10_integration
A22: C. CROSS-STAGE CONSISTENCY CHECKS (live assertions — recompute on open)
B23: Check | C23: Expected | D23: Actual | E23: Diff | F23: Verdict
B24: Stage 9 cost-stack E1 total = Stage 6 (2026) | C24: =stage6_decomp!F166 | D24: =stage9_policy!D11 | E24: =C24-D24 | F24: =IF(ABS(E24)<0.01,"PASS","FAIL")
B25: Golden GN1b (UK XL incl CCL) reproduces | C25: 290.5 | D25: =golden_numbers!K6 | E25: =C25-D25 | F25: =IF(ABS(E25)<0.5,"PASS","FAIL")
B26: Golden GN2 (TNUoS residual /MWh) reproduces | C26: 12.32 | D26: =golden_numbers!K7 | E26: =C26-D26 | F26: =IF(ABS(E26)<0.05,"PASS","FAIL")
B27: Stage 6 UK large E1 reconciliation = 0 (max |2010–25|) | C27: 0 | D27: =SUMPRODUCT(MAX(ABS(stage6_decomp!E13:T13))) | E27: =C27-D27 | F27: =IF(ABS(E27)<0.001,"PASS","FAIL")
B28: Stage 9 who-pays UK E2 cost = Stage 6 T3 | C28: =stage6_decomp!G149 | D28: =stage9_policy!F16 | E28: =C28-D28 | F28: =IF(ABS(E28)<0.01,"PASS","FAIL")
A30: D. WORKBOOK INTEGRITY PANEL (live counts)
B31: Metric | C31: Value | D31: Target | E31: Verdict
B32: Stage 6 reconciliation gates = PASS (internal, by construction — Q46) | C32: =COUNTIF(stage6_decomp!A1:T200,"PASS") | D32: 151 | E32: =IF(C32>=D32,"PASS","CHECK")
B33: Stage 6 gates = FAIL (must be 0) | C33: =COUNTIF(stage6_decomp!A1:T200,"FAIL") | D33: 0 | E33: =IF(C33=0,"PASS","FAIL")
B34: Consistency checks passing (Section C) | C34: =COUNTIF(F24:F28,"PASS") | D34: 5 | E34: =IF(C34=D34,"PASS","FAIL")
B35: Sheets in workbook | C35: =_xlfn.SHEETS() | D35: 24 | E35: =IF(C35=D35,"PASS","FAIL")
B36: Independent validation (not by construction) | C36: GN anchors reproduce (Section C); observed-vs-modelled gates: DE large PASS; UK large/medium & DE medium FAIL 2025 — supply-margin wedge, an exhibit (Q30; timeseries r92–95) | D36: — | E36: RECORDED
A37: E. OVERALL CONCLUSION
B38: UK industrial electricity is expensive for different reasons against different peers. Against GERMANY the modelled system cost is similar (UK $207 vs DE $211 large; $213 vs $231 medium) — network+system and taxes are LOWER in the UK — and the E1 on-bill gap ($207 vs $170) is driven by policy/generation-capital recovery on bills (UK $60 vs DE $12) plus slightly dearer gas-set wholesale; the real UK–DE difference is WHO PAYS. Against CHINA the whole stack sits above (~$87 on-bill, administratively held down, industry cross-subsidising households). Network is the fastest-RISING bucket (UK residual +94% 25/26→26/27) though not above Germany's 2025 level at the large archetype. Relief relocates cost rather than removing it: the UK is moving EII relief off other bill-payers toward Exchequer + energy-system funding (BICS; final split at Budget 2026) — converging on the German taxpayer model. Supply-side options offer little near-term relief; cost-REDUCING levers (gas dependence, network growth, carbon design) are structural and slow. The modelled stack is a statutory floor: observed 2025 bills run ~$80/MWh higher (supply margin, Section A row 9). Policy choice is therefore less about the size of the stack than about who is asked to pay it — and about the slow structural work that actually lowers it.
A40: Decisions D57–D62 · QC Q73–Q82 · this front page is Stage 10. Study complete pending owner approval. Real-2025 USD; VAT excluded; blanks = unavailable (never zero). External-review fix pass 2026-07-19 (Q82/D61–D62): modelled-vs-observed labelling, conclusion aligned to decomposition, BICS funding pending Budget 2026, steel coefficients re-derived. PUBLICATION SPINE per D64 (ChatGPT v40 = challenge annex).

Sheet assumptions
A1: ASSUMPTIONS — editable inputs driving the build-up (stage 1, locked per project instructions)
A2: Blue = hardcoded input (editable). Yellow = key assumption. All verified against primary sources 2026-07-14; see sources tab.
A4: A. ARCHETYPES (locked — house rule 2)
A5: Parameter | B5: Large industrial | C5: Medium industrial | D5: Notes / verification
A6: Annual consumption (MWh/yr) | B6: 500000 | C6: 20000 | D6: Locked.
A7: Load factor / utilisation hours (h/yr) | B7: 8000 | C7: 5000 | D7: Highest-leverage assumption. Mandatory sensitivity at 6,500h (cell B_sens below).
A8: Implied average demand (MW) | B8: =B6/B7 | C8: =C6/C7 | D8: Formula: consumption / hours. Large ≈62.5 MW, medium 4 MW.
A9: Connection — UK | B9: Transmission / EHV | C9: 11–33kV (HV, distribution) | D9: 132kV = distribution in England & Wales, transmission in Scotland — VERIFIED: Electricity Act 1989 s.64(1) & s.4(4), legislation.gov.uk, retr. 2026-07-14.
A10: Connection — DE | B10: Höchst-/Hochspannung | C10: Mittelspannung | D10: Standard German voltage-level taxonomy (StromNEV).
A11: Connection — CN | B11: 220kV及以上 | C11: 10(20)kV | D11: 526号文 tariff classes: 不满1kV / 1-10(20)kV / 35kV / 110kV / 220kV+. RESOLVED (D10, user 2026-07-14): 10(20)kV — physically typical for ~5,000 kVA; conservative. 35kV reported as intra-country spread (Jiangsu T&D ≈ −13% at 35kV).
A13: B. SITES & VERIFIED NETWORK PARAMETERS
A14: Parameter | B14: Value | C14: Applies to | D14: Source / verification (retr. 2026-07-14)
A15: UK site | B15: Humber | C15: both | D15: Locked. Real EII cluster (Immingham/Scunthorpe/Hull).
A16: UK TNUoS demand zone | B16: Zone 5 — Yorkshire | C16: both | D16: NESO Final TNUoS Tariffs 2025/26 v1.0, App. H p.68: zone 5/7 boundary runs south of the Humber; BOTH banks in zone 5.
A17: UK TNUoS locational demand tariff 2025/26 (£/kW) | B17: 0 | C17: large | D17: Zone 5 zero-floored ('Zones 1–7 subject to the zero floor'), Table 9 p.22, Table 11 p.24. Pre-floor: Peak −0.790016, Year Round −4.258236 £/kW (Table 25 p.52).
A18: UK TCR band — large (transmission) | B18: T-Demand4 | C18: large | D18: 500,000 MWh > 189,873 MWh threshold (25/26) and > 163,880 (26/27). NESO Tables sheet TB.
A19: UK TCR residual 2025/26 (£/site/day) | B19: 12796.715 | C19: large | D19: NESO Final TNUoS 2025/26, Table 10 p.23. Band has 5 sites.
A20: UK TCR residual 2026/27 (£/site/day) | B20: 20829.237 | C20: large | D20: NESO Final TNUoS 2026/27, Tables T10/TB. Thresholds re-set for RIIO-3.
A21: UK DNO — both Humber banks | B21: Northern Powergrid (Yorkshire) | C21: medium | D21: VERIFIED: North Lincolnshire is Northern Powergrid, NOT NGED East Midlands (nationalgrid.com Grimsby-Walpole 'Need for project'; northernpowergrid.com/about-us). See decision D5. Licence-name attribution high-confidence, not document-level (qc log).
A22: UK DUoS statement — medium | B22: NPg (Yorkshire) LC14 CDCM 2025-26 | C22: medium | D22: Title verified via site index only (JS-rendered page) — flagged in qc.
A23: UK TCR band — medium (inferred) | B23: HV4 — £317.597969/site/day | C23: medium | D23: INFERRED from published kVA thresholds (HV4 >1,800 kVA); allocation is done by DNO on agreed capacity. estimated=Y; qc log.
A24: DE site | B24: Rhine-Ruhr | C24: both | D24: Locked.
A25: DE TSO | B25: Amprion | C25: large | D25: amprion.net 'Unser Netz' — control area covers NRW/Rhine-Ruhr.
A26: DE transmission charges harmonised? | B26: Yes, since 01.01.2023 | C26: large | D26: StromNEV §3(3), §§14a–14d (bundeseinheitliche ÜNB-Entgelte), gesetze-im-internet.de. Joint ÜNB price sheet 2026 dated 05.12.2025, netztransparenz.de. Locational variable is therefore the DSO region, as hypothesised.
A27: DE DSO | B27: Westnetz | C27: medium | D27: Largest German DSO, Rhine-Ruhr footprint; exact service-area sentence not readable on rendered page (qc log).
A28: DE §19(2) StromNEV — large archetype | B28: Qualifies, Satz 2/3 Nr.3 (≥8,000h & >10 GWh) → floor 10% | C28: large | D28: StromNEV §19(2) current text, gesetze-im-internet.de: floors 20/15/10% at 7,000/7,500/8,000h — FLOORS, not tariffs. In force through 2028; abolition scheduled with StromNEV expiry end-2028, Bandlast grandfathering intended to 31.12.2031 (BNetzA AgNes Orientierungspunkte 22.04.2026, GBK-25-01-1#3, p.17).
A29: DE §19(2) — medium archetype | B29: Does NOT qualify (5,000h < 7,000h) | C29: medium | D29: Satz 2 requires ≥7,000h AND >10 GWh. Atypical-use limb (Satz 1) fails for baseload — to establish in stage 4, not assumed.
A30: DE 2026 transmission subsidy | B30: €6.5bn, federal (KTF) | C30: both | D30: §24c EnWG; Gesetz BGBl. 2025 I Nr. 317, in force 12.12.2025; 2026 only. Deducted from revenue caps → ~57% cut in avg HöS charge (TSO-sourced, verbatim unverified — qc). Incidence: (iii) taxpayer.
A31: CN provincial basket | B31: JS, GD, SD, ZJ, HN, IM, SC | C31: both | D31: Locked. Weights below, 2024 vintage (decision D2), held constant.
A32: CN weight set driving build-up | B32: C | C32: both | D32: TOGGLE: 'A' = closest-to-industrial (mixed categories); 'B' = 全社会 totals; 'C' = 第二产业 secondary industry, consistent basis, with fallbacks for GD (工业) and SC (全社会). RESOLVED (D11, user 2026-07-14): Set C.
A34: C. CHINESE BASKET WEIGHTS (2024 consumption, 亿千瓦时; weights computed = estimated Y). Active set: C (decision D11).
A35: Province | B35: Set A: closest-to-industrial (亿kWh) | C35: Set B: 全社会 total (亿kWh) | D35: Set C: 第二产业 (亿kWh) | E35: Category & source flag
A36: Jiangsu 江苏 | B36: 5752 | C36: 8487 | D36: 5752 | E36: Set A = Set C = 第二产业 (SGCC Jiangsu 2024 CSR data via jiangsu.gov.cn 2025-03-26); 全社会 8486.93 per NEA Jiangsu office.
A37: Guangdong 广东 | B37: 5216.25 | C37: 9121.03 | D37: 5216.25 | E37: FLAG (Set C): GD publishes NO 第二产业 aggregate (checked grid, energy bureau, 统计年鉴2025 表7-6) — fallback to 工业 5216.25 per D11. Derived alternative 工业5217.39+建筑业102.68=5320.07 (yearbook 7-6, NBS energy classification) noted, not used.
A38: Shandong 山东 | B38: 6005.1 | C38: 8319.7 | D38: 6071.1 | E38: Set A = 工业; Set C = 第二产业 6071.1 (+2.8%) — Shandong Statistics Bureau note 2025-01-22, VERIFIED.
A39: Zhejiang 浙江 | B39: 4435.4 | C39: 6780 | D39: 4515.5 | E39: Set A = 工业; Set C = 第二产业 4515.5 (+7.8%) — 国网浙江 via 新华网 2025-01-20, VERIFIED (grid-company data flag).
A40: Henan 河南 | B40: 2283.25 | C40: 4319.94 | D40: 2330.71 | E40: Set A = 工业; Set C = 第二产业 2330.71 (本年累计, NEA Henan Table 2; row check 87.14+2330.71+925.09+977=4319.94 ✓), VERIFIED.
A41: Inner Mongolia 内蒙古 | B41: 4539.12 | C41: 5193.41 | D41: 4539.12 | E41: Set A = Set C = 第二产业. FLAG: source is industry-association republication of grid statistics (now read directly; no better official source exists — 2024 statistical bulletin has no consumption breakdown). Swing constituent — report basket with/without.
A42: Sichuan 四川 | B42: 4000 | C42: 4000 | D42: 2404.56 | E42: Set C = 第二产业 2404.56 亿千瓦时 (2024, +3.36%) — Q6 CLOSED 2026-07-15 via 硕电汇/北极星 year-end summary (news.bjx.com.cn/html/20250123/1424280.shtml, image tables); components sum to 全社会 3999.69 exactly (38.84+2404.56+780.93+775.36). Set A/B still 全社会 placeholder 4000 — flagged (active set = C per D11).
A43: Sum | B43: =SUM(B36:B42) | C43: =SUM(C36:C42) | D43: =SUM(D36:D42)
...

Sheet fx_deflator
A1: FX & DEFLATOR — Fed H.10/G.5A annual averages (FRED); BLS CPI-U CUUR0000SA0 M13. Retrieved 2026-07-14.
A2: G.5A release 05.01.2026 cross-checks FRED exactly for 2022–2025. CPI-U 2025 final per BLS API (no footnote flag). No 2026 annual averages exist yet — any 2026 conversion is provisional (decision D6).
H3: HELPER — contiguous 2010–2026 lookup for timeseries formulas (references the blocks above; 2026 FX blank per D6)
A4: Year | B4: USD per GBP | C4: USD per EUR | D4: CNY per USD | E4: CPI-U (1982-84=100) | F4: Deflator to 2025 | H4: Year | I4: USD per GBP | J4: USD per EUR | K4: CNY per USD | L4: CPI-U | M4: Deflator to 2025
A5: 2020 | B5: 1.2829 | C5: 1.141 | D5: 6.9042 | E5: 258.811 | F5: =$E$10/E5 | H5: 2010 | I5: =B13 | J5: =C13 | K5: =D13 | L5: =E13 | M5: =F13
A6: 2021 | B6: 1.3764 | C6: 1.183 | D6: 6.4508 | E6: 270.97 | F6: =$E$10/E6 | H6: 2011 | I6: =B14 | J6: =C14 | K6: =D14 | L6: =E14 | M6: =F14
A7: 2022 | B7: 1.2371 | C7: 1.0534 | D7: 6.729 | E7: 292.655 | F7: =$E$10/E7 | H7: 2012 | I7: =B15 | J7: =C15 | K7: =D15 | L7: =E15 | M7: =F15
A8: 2023 | B8: 1.244 | C8: 1.0817 | D8: 7.0809 | E8: 304.702 | F8: =$E$10/E8 | H8: 2013 | I8: =B16 | J8: =C16 | K8: =D16 | L8: =E16 | M8: =F16
A9: 2024 | B9: 1.2781 | C9: 1.082 | D9: 7.1957 | E9: 313.689 | F9: =$E$10/E9 | H9: 2014 | I9: =B17 | J9: =C17 | K9: =D17 | L9: =E17 | M9: =F17
A10: 2025 | B10: 1.3192 | C10: 1.1306 | D10: 7.1875 | E10: 321.943 | F10: =$E$10/E10 | H10: 2015 | I10: =B18 | J10: =C18 | K10: =D18 | L10: =E18 | M10: =F18
H11: 2016 | I11: =B19 | J11: =C19 | K11: =D19 | L11: =E19 | M11: =F19
A12: Additional years: CPI-U (BLS API, retr. 2026-07-14); FX 2010–2019 added 2026-07-15 (FRED fredgraph.csv annual avg: DEXUSUK, DEXUSEU, DEXCHUS — Fed H.10, per D1). | H12: 2017 | I12: =B20 | J12: =C20 | K12: =D20 | L12: =E20 | M12: =F20
A13: 2010 | B13: 1.5452 | C13: 1.3261 | D13: 6.7696 | E13: 218.056 | F13: =$E$10/E13 | H13: 2018 | I13: =B21 | J13: =C21 | K13: =D21 | L13: =E21 | M13: =F21
A14: 2011 | B14: 1.6043 | C14: 1.3931 | D14: 6.463 | E14: 224.939 | F14: =$E$10/E14 | H14: 2019 | I14: =B22 | J14: =C22 | K14: =D22 | L14: =E22 | M14: =F22
A15: 2012 | B15: 1.5853 | C15: 1.2859 | D15: 6.3093 | E15: 229.594 | F15: =$E$10/E15 | H15: 2020 | I15: =B5 | J15: =C5 | K15: =D5 | L15: =E5 | M15: =F5
A16: 2013 | B16: 1.5642 | C16: 1.3281 | D16: 6.1478 | E16: 232.957 | F16: =$E$10/E16 | H16: 2021 | I16: =B6 | J16: =C6 | K16: =D6 | L16: =E6 | M16: =F6
A17: 2014 | B17: 1.6484 | C17: 1.3297 | D17: 6.162 | E17: 236.736 | F17: =$E$10/E17 | H17: 2022 | I17: =B7 | J17: =C7 | K17: =D7 | L17: =E7 | M17: =F7
A18: 2015 | B18: 1.5284 | C18: 1.1096 | D18: 6.2827 | E18: 237.017 | F18: =$E$10/E18 | H18: 2023 | I18: =B8 | J18: =C8 | K18: =D8 | L18: =E8 | M18: =F8
A19: 2016 | B19: 1.3555 | C19: 1.1072 | D19: 6.64 | E19: 240.007 | F19: =$E$10/E19 | H19: 2024 | I19: =B9 | J19: =C9 | K19: =D9 | L19: =E9 | M19: =F9
A20: 2017 | B20: 1.289 | C20: 1.1301 | D20: 6.7569 | E20: 245.12 | F20: =$E$10/E20 | H20: 2025 | I20: =B10 | J20: =C10 | K20: =D10 | L20: =E10 | M20: =F10
A21: 2018 | B21: 1.3363 | C21: 1.1817 | D21: 6.609 | E21: 251.107 | F21: =$E$10/E21 | H21: 2026
A22: 2019 | B22: 1.2768 | C22: 1.1194 | D22: 6.9081 | E22: 255.657 | F22: =$E$10/E22

Sheet golden_numbers
A1: GOLDEN NUMBERS — published anchors reproduced through the full house-rule pipeline (nominal local → Fed H.10 annual-avg FX → US CPI-U → real 2025 USD/MWh). Permanent regression tests.
A2: Set approved by user 2026-07-14 (decision D3). Conversion columns are FORMULAS reading fx_deflator and assumptions. 'estimated=Y' marks any computed (not retrieved) step. Excludes VAT throughout.
A4: GN | B4: Description | C4: As-published value | D4: Native unit | E4: Data year | F4: FX year | G4: Local /MWh | H4: FX rate | I4: Nominal USD/MWh | J4: Deflator | K4: Real 2025 USD/MWh | L4: estimated? | M4: Modelled/observed | N4: Citation (source — table/page — URL — retrieved 2026-07-14)
A5: GN1a | B5: DESNZ QEP: UK non-domestic electricity price, Extra Large band (>150,000 MWh/yr), 2024 annual, EXCL CCL, excl VAT | C5: 21.697865 | D5: p/kWh | E5: 2024 | F5: 2024 | G5: =C5*10 | H5: =fx_deflator!$B$9 | I5: =IF(D5="CNY/MWh basis",G5/H5,G5*H5) | J5: =fx_deflator!$F$9 | K5: =I5*J5 | L5: N | M5: Observed (published) | N5: DESNZ QEP, Gas & electricity prices in the non-domestic sector, table_341.xlsx, sheet '3.4.1 (Annual excl CCL)' (pub. 30.06.2026) — https://assets.publishing.service.gov.uk/media/6942bd3536f089d38be1f246/table_341.xlsx — retr. 2026-07-14. Displays as 21.70. Note: 3.4.x = non-domestic consumers (not the GB manufacturing tables 3.1.x).
A6: GN1b | B6: Same, INCLUDING CCL (variant) | C6: 22.146382 | D6: p/kWh | E6: 2024 | F6: 2024 | G6: =C6*10 | H6: =fx_deflator!$B$9 | I6: =IF(D6="CNY/MWh basis",G6/H6,G6*H6) | J6: =fx_deflator!$F$9 | K6: =I6*J6 | L6: N | M6: Observed (published) | N6: Same file, sheet '3.4.2 (Annual inc CCL)'. Displays as 22.15. VAT excluded in both.
A7: GN2 | B7: NESO TNUoS 2025/26, T-Demand4 residual (Humber zone 5; locational tariff = 0, zero-floored). Per-MWh line converts the published £/site/day through the LARGE archetype (×365 ÷ assumptions!B6) — construction check, computed | C7: 12796.715 | D7: £/site/day | E7: 2025 | F7: 2025 | G7: =C7*365/assumptions!$B$6 | H7: =fx_deflator!$B$10 | I7: =IF(D7="CNY/MWh basis",G7/H7,G7*H7) | J7: =fx_deflator!$F$10 | K7: =I7*J7 | L7: Y | M7: Published tariff; per-MWh step modelled | N7: NESO, Final TNUoS Tariffs 2025/26 v1.0 (31.01.2025), Table 10 p.23 (residual), Table 9 p.22 & Table 11 p.24 (zero floor zones 1–7), App. H p.68 (zone map) — https://www.neso.energy/document/353086/download — retr. 2026-07-14. 2026/27: £20,829.236682/site/day (doc 376336/376341). FX-year mapping per decision D4.
A8: GN3 | B8: BDEW Strompreisanalyse (Apr 2026 ed.): industrial price, kleine/mittlere Industrie Musterkunde (avg of 5 cases 160 MWh–20 GWh/yr, Mittelspannung, new contracts, incl reduced Stromsteuer), 2025 annual | C8: 17.6 | D8: ct/kWh | E8: 2025 | F8: 2025 | G8: =C8*10 | H8: =fx_deflator!$C$10 | I8: =IF(D8="CNY/MWh basis",G8/H8,G8*H8) | J8: =fx_deflator!$F$10 | K8: =I8*J8 | L8: N | M8: Observed (published) | N8: BDEW-Strompreisanalyse April 2026 (15.04.2026), Folie 12 annual series (2024: 17.3; 2026: 16.7) — https://www.bdew.de/media/documents/BDEW_Strompreisanalyse_042026.pdf — retr. 2026-07-14. 2026 figure NOT converted: no 2026 annual FX exists yet (decision D6). Closest match to MEDIUM archetype.
A9: GN4s1 | B9: Eurostat nrg_pc_205, DE, band IF (70–150 GWh), 2024-S1, X_VAT (excl VAT & other recoverable) | C9: 0.1394 | D9: EUR/kWh | E9: 2024 | F9: 2024 | G9: =C9*1000 | H9: =fx_deflator!$C$9 | I9: =IF(D9="CNY/MWh basis",G9/H9,G9*H9) | J9: =fx_deflator!$F$9 | K9: =I9*J9 | L9: N | M9: Observed (published) | N9: Eurostat dissemination API, nrg_pc_205, geo=DE, nrg_cons=MWH70000-149999, tax=X_VAT, currency=EUR (dataset update 2026-05-19) — retr. 2026-07-14. X_TAX variant: 0.1276 (S1) / 0.1313 (S2).
A10: GN4s2 | B10: Same, 2024-S2 | C10: 0.143 | D10: EUR/kWh | E10: 2024 | F10: 2024 | G10: =C10*1000 | H10: =fx_deflator!$C$9 | I10: =IF(D10="CNY/MWh basis",G10/H10,G10*H10) | J10: =fx_deflator!$F$9 | K10: =I10*J10 | L10: N | M10: Observed (published) | N10: As GN4s1.
A11: GN4 | B11: Eurostat IF DE 2024 annual = simple semester average — COMPUTED (Eurostat publishes no annual value) | G11: =(G9+G10)/2 | H11: =fx_deflator!$C$9 | I11: =G11*H11 | J11: =fx_deflator!$F$9 | K11: =I11*J11 | L11: Y | M11: Computed from published | N11: Average of GN4s1/GN4s2. estimated=Y.
A12: GN5a | B12: NDRC 526号文: Jiangsu T&D price (输配电价), 工商业 two-part, 220kV+, VOLUMETRIC 电量电价 (3rd regulatory period, eff. 01.06.2023; still applied in SGCC Jiangsu Mar-2026 agency-purchase notice) 含税 as published (Q84). | C12: 0.0597 | D12: CNY/MWh basis | E12: 2025 | F12: 2025 | G12: =C12*1000 | H12: =fx_deflator!$D$10 | I12: =IF(D12="CNY/MWh basis",G12/H12,G12*H12) | J12: =fx_deflator!$F$10 | K12: =I12*J12 | L12: N | M12: Observed (published) | N12: 国家发展改革委 发改价格〔2023〕526号, annex 省级电网输配电价表, 江苏 row 工商业·两部制 — https://www.ndrc.gov.cn/xxgk/zcfb/tz/202305/P020230515609052875117.pdf — retr. 2026-07-14. Cross-check: SGCC Jiangsu 2026-03 代理购电公告 附件6 (0.0597 / 41.6 / 26.0). Includes VAT & base-period cross-subsidy; excludes 政府性基金及附加, line loss (3.18%), pumped-storage capacity fee. Native unit 元/千瓦时.
A13: GN5b | B13: Same row: DEMAND charge 需量电价 41.6 元/kW·月, converted to per-MWh through the LARGE archetype: ×12 months ÷ (hours×MW→MWh per kW = B7/1000) — computed | C13: 41.6 | D13: CNY/MWh basis | E13: 2025 | F13: 2025 | G13: =C13*12/(assumptions!$B$7/1000) | H13: =fx_deflator!$D$10 | I13: =IF(D13="CNY/MWh basis",G13/H13,G13*H13) | J13: =fx_deflator!$F$10 | K13: =I13*J13 | L13: Y | M13: Published tariff; per-MWh step modelled | N13: Same table/row, column 需量电价. Capacity variant 容量电价 26.0 元/kVA·月. At 8,000h: 499.2 元/kW·yr ÷ 8 MWh/kW = 62.4 元/MWh. Load-factor sensitivity runs through assumptions!B7.
A14: GN5 | B14: Jiangsu 220kV all-in T&D for large archetype (volumetric + demand) — construction check | I14: =I12+I13 | J14: =fx_deflator!$F$10 | K14: =I14*J14 | L14: Y | M14: Modelled from published | N14: Sum of GN5a + GN5b nominal USD. Note 4th-period notice (发改价格〔2026〕1077号, reported 10.07.2026) reportedly supersedes from 2026 — UNVERIFIED at primary level, see qc Q1.
A16: Chart/table footnote (house rule 1): "Real 2025 USD/MWh. Converted at annual-average market FX. Excludes VAT (UK/DE; CN carried 含税 as published — Q84)."

Sheet lcoe
A1: LCOE COMPARISON — UK / DE / CN (stage 3). LCOE IS CONTEXT, NOT CAUSE: it is not the driver of industrial retail prices; the archetype build-up (stages 4/6) is the study's spine.
A2: Footnote (all USD columns): Real 2025 USD/MWh. Converted at annual-average market FX. Excludes VAT. As-published values quoted exactly in native units/price base; every conversion and every modelled figure is estimated=Y.
A4: 1. AS-PUBLISHED LCOE + MANDATORY ASSUMPTIONS (WACC, CF, fuel, carbon, lifetime, capex)
A5: Ctry | B5: Technology | C5: Source / edition | D5: LCOE low | E5: LCOE high/pt | F5: Native unit | G5: Price base | H5: Data yr | I5: WACC (native) | J5: WACC basis | K5: CF / FLH | L5: Life (y) | M5: Capex as published | N5: Fuel assumption | O5: Carbon assumption | P5: estimated? | Q5: Real25 USD low | R5: Real25 USD high/pt | S5: Citation (retrieved 2026-07-14)
A6: UK | B6: CCGT H-class | C6: DESNZ EGC 2023, Tbl 10 + Annex A | E6: 114 | F6: £/MWh | G6: real 2021 GBP | H6: 2025 comm. | I6: 7.5% | J6: hurdle, pre-tax real | K6: 93% LF | L6: 25 | M6: £610/kW + infra | N6: component £43/MWh (EGC 2023 basis) | O6: component £60/MWh | P6: N | R6: =E6*fx_deflator!$B$6*fx_deflator!$F$6 | S6: DESNZ, Electricity Generation Costs 2023 (Nov 2023), Table 10 p.24; Annex A 2023 sheets 'Additional estimates 2025' / 'Technical and cost assumptions' — gov.uk — retr. 2026-07-14. USER DECISION D16: 2023 edition used for 2025 commissioning; EGC 2025 (Jan 2026) starts at 2030 and uses a different carbon methodology — not like-for-like.
A7: UK | B7: OCGT (300MW, 2000h) | C7: DESNZ EGC 2023, Annex A | E7: 197 | F7: £/MWh | G7: real 2021 GBP | H7: 2025 comm. | I7: 7.1% | J7: hurdle, pre-tax real | K7: 22% LF | L7: 25 | M7: £530/kW + infra | N7: component £67/MWh | O7: component £94/MWh | P7: N | R7: =E7*fx_deflator!$B$6*fx_deflator!$F$6 | S7: Annex A 2023, 'Additional estimates 2025', column 'OCGT 300MW 2000 hr' Total = 197.
A8: UK | B8: Onshore wind | C8: DESNZ EGC 2023, Tbl 10 | E8: 38 | F8: £/MWh | G8: real 2021 GBP | H8: 2025 comm. | I8: 5.2% | J8: hurdle, pre-tax real | K8: 45% LF | L8: 25 | M8: £1,230/kW + infra | N8: — | O8: — | P8: N | R8: =E8*fx_deflator!$B$6*fx_deflator!$F$6 | S8: Table 10 p.24.
A9: UK | B9: Offshore wind | C9: DESNZ EGC 2023, Tbl 10 | E9: 44 | F9: £/MWh | G9: real 2021 GBP | H9: 2025 comm. | I9: 6.3% | J9: hurdle, pre-tax real | K9: 61% LF | L9: 30 | M9: £1,630/kW + infra | N9: — | O9: — | P9: N | R9: =E9*fx_deflator!$B$6*fx_deflator!$F$6 | S9: Table 10 p.24.
A10: UK | B10: Solar PV (large) | C10: DESNZ EGC 2023, Tbl 10 | E10: 41 | F10: £/MWh | G10: real 2021 GBP | H10: 2025 comm. | I10: 5.0% | J10: hurdle, pre-tax real | K10: 11% LF | L10: 35 | M10: £450/kW + infra | N10: — | O10: — | P10: N | R10: =E10*fx_deflator!$B$6*fx_deflator!$F$6 | S10: Table 10 p.24.
A11: UK | B11: Coal | C11: — | P11: GAP | S11: NOT COVERED by DESNZ series (recent editions). Gap is a finding.
A12: UK | B12: Nuclear | C12: — | P12: GAP | S12: NOT PUBLISHED: EGC 2025 withholds Sizewell C / SMR costs as commercially sensitive; no nuclear LCOE in 2023/2020 editions (last: 2016 edition, not retrieved).
A13: DE | B13: Lignite (new build) | C13: Fraunhofer ISE Jul 2024 | D13: 15.1 | E13: 25.7 | F13: ct/kWh | G13: real 2024 EUR | H13: 2024 | I13: 6.8% | J13: WACC real (nom 8.6%) | K13: 4,300–6,300 FLH | L13: 40 | M13: €1,850–2,550/kW | N13: €2.3/MWh_th | O13: EU ETS €75–90/t (2024) | P13: N | Q13: =D13*10*fx_deflator!$C$9*fx_deflator!$F$9 | R13: =E13*10*fx_deflator!$C$9*fx_deflator!$F$9 | S13: Fraunhofer ISE, Stromgestehungskosten Erneuerbare Energien, Juli 2024, pp.3/19 (bands), Tabellen 1–7 (assumptions) — ise.fraunhofer.de — retr. 2026-07-14. Bands: low capex+best resource / high capex+worst.
A14: DE | B14: Hard coal (new build) | C14: Fraunhofer ISE Jul 2024 | D14: 17.3 | E14: 29.3 | F14: ct/kWh | G14: real 2024 EUR | H14: 2024 | I14: 6.8% | J14: WACC real | K14: 3,000–5,200 FLH | L14: 30 | M14: €1,700–2,300/kW | N14: €11.6/MWh_th | O14: EU ETS €75–90/t | P14: N | Q14: =D14*10*fx_deflator!$C$9*fx_deflator!$F$9 | R14: =E14*10*fx_deflator!$C$9*fx_deflator!$F$9 | S14: Same, pp.3/19.
A15: DE | B15: CCGT (GuD) | C15: Fraunhofer ISE Jul 2024 | D15: 10.9 | E15: 18.1 | F15: ct/kWh | G15: real 2024 EUR | H15: 2024 | I15: 6.4% | J15: WACC real | K15: 3,000–6,300 FLH | L15: 30 | M15: €900–1,300/kW | N15: €38/MWh_th (27 from 2030) | O15: EU ETS €75–90/t | P15: N | Q15: =D15*10*fx_deflator!$C$9*fx_deflator!$F$9 | R15: =E15*10*fx_deflator!$C$9*fx_deflator!$F$9 | S15: Same, pp.3–4/19 (p.4 prints 18.0 — internal source discrepancy, flagged qc).
A16: DE | B16: OCGT (Gasturbine) | C16: Fraunhofer ISE Jul 2024 | D16: 15.4 | E16: 32.6 | F16: ct/kWh | G16: real 2024 EUR | H16: 2024 | I16: 6.4% | J16: WACC real | K16: 500–3,000 FLH | L16: 30 | M16: €450–700/kW | N16: €38/MWh_th | O16: EU ETS €75–90/t | P16: N | Q16: =D16*10*fx_deflator!$C$9*fx_deflator!$F$9 | R16: =E16*10*fx_deflator!$C$9*fx_deflator!$F$9 | S16: Same, pp.3/19.
A17: DE | B17: Onshore wind | C17: Fraunhofer ISE Jul 2024 | D17: 4.3 | E17: 9.2 | F17: ct/kWh | G17: real 2024 EUR | H17: 2024 | I17: 3.9% | J17: WACC real | K17: 1,800–3,200 FLH | L17: 25 | M17: €1,300–1,900/kW | N17: — | O17: — | P17: N | Q17: =D17*10*fx_deflator!$C$9*fx_deflator!$F$9 | R17: =E17*10*fx_deflator!$C$9*fx_deflator!$F$9 | S17: Same, pp.3/19.
A18: DE | B18: Offshore wind | C18: Fraunhofer ISE Jul 2024 | D18: 5.5 | E18: 10.3 | F18: ct/kWh | G18: real 2024 EUR | H18: 2024 | I18: 6.0% | J18: WACC real | K18: 3,200–4,500 FLH | L18: 25 | M18: €2,200–3,400/kW (incl. shore connection) | N18: — | O18: — | P18: N | Q18: =D18*10*fx_deflator!$C$9*fx_deflator!$F$9 | R18: =E18*10*fx_deflator!$C$9*fx_deflator!$F$9 | S18: Same, pp.3/19.
A19: DE | B19: Solar PV (Freifläche) | C19: Fraunhofer ISE Jul 2024 | D19: 4.1 | E19: 6.9 | F19: ct/kWh | G19: real 2024 EUR | H19: 2024 | I19: 3.5% | J19: WACC real | K19: 935–1,280 kWh/kWp | L19: 30 | M19: €700–900/kW | N19: — | O19: — | P19: N | Q19: =D19*10*fx_deflator!$C$9*fx_deflator!$F$9 | R19: =E19*10*fx_deflator!$C$9*fx_deflator!$F$9 | S19: Same, pp.18–19/21.
A20: DE | B20: Nuclear (new build) | C20: Fraunhofer ISE Jul 2024 | D20: 13.6 | E20: 49 | F20: ct/kWh | G20: real 2024 EUR | H20: 2024 | I20: 7.8% | J20: WACC real | K20: 4,300–6,300 FLH | L20: 45 | M20: €6,000–16,000/kW | N20: uranium €8/MWh_th | O20: — | P20: N | Q20: =D20*10*fx_deflator!$C$9*fx_deflator!$F$9 | R20: =E20*10*fx_deflator!$C$9*fx_deflator!$F$9 | S20: Same, pp.3/19. EXCLUDES back-end/decommissioning/final storage (p.3) — health warning on any chart.
A21: CN | B21: Coal (new build) | C21: IEA WEO 2025, Tbl B.4a | E21: 65 | F21: USD/MWh | G21: 2024 USD | H21: 2024 | I21: 8–9% | J21: standard WACC, thermal | K21: 50% CF | L21: n/p | M21: $800/kW | N21: 10-yr avg from 2024 | O21: in scenario | P21: N | R21: =E21*fx_deflator!$F$9 | S21: IEA, World Energy Outlook 2025 (12.11.2025), Annex B, Table B.4a p.454 (2024 values identical in B.4b) — iea.org — retr. 2026-07-14. USER DECISION D17: international analyses for CN thermal/nuclear.
A22: CN | B22: Gas CCGT | C22: IEA WEO 2025, Tbl B.4a | E22: 100 | F22: USD/MWh | G22: 2024 USD | H22: 2024 | I22: 8–9% | J22: standard WACC, thermal | K22: 30% CF | L22: n/p | M22: $560/kW | N22: 10-yr avg from 2024 | O22: in scenario | P22: N | R22: =E22*fx_deflator!$F$9 | S22: Same table.
A23: CN | B23: Nuclear | C23: IEA WEO 2025, Tbl B.4a | E23: 70 | F23: USD/MWh | G23: 2024 USD | H23: 2024 | I23: 8–9% | J23: standard WACC | K23: 75% CF | L23: n/p | M23: $2,800/kW (NOAK) | N23: — | O23: — | P23: N | R23: =E23*fx_deflator!$F$9 | S23: Same table.
A24: CN | B24: Solar PV (utility) | C24: IEA WEO 2025, Tbl B.4a | E24: 45 | F24: USD/MWh | G24: 2024 USD | H24: 2024 | I24: 4–7% | J24: Cost of Capital Observatory | K24: 12% CF | L24: n/p | M24: $590/kW | N24: — | O24: — | P24: N | R24: =E24*fx_deflator!$F$9 | S24: Same table.
A25: CN | B25: Onshore wind | C25: IEA WEO 2025, Tbl B.4a | E25: 40 | F25: USD/MWh | G25: 2024 USD | H25: 2024 | I25: 4–7% | J25: as PV | K25: 23% CF | L25: n/p | M25: $860/kW | N25: — | O25: — | P25: N | R25: =E25*fx_deflator!$F$9 | S25: Same table.
A26: CN | B26: Offshore wind | C26: IEA WEO 2025, Tbl B.4a | E26: 60 | F26: USD/MWh | G26: 2024 USD | H26: 2024 | I26: 5–8% | J26: offshore band | K26: 30% CF | L26: n/p | M26: $1,520/kW | N26: — | O26: — | P26: N | R26: =E26*fx_deflator!$F$9 | S26: Same table.
A27: CN | B27: Solar PV (utility) | C27: CREEI 造价报告 2024 (28.05.2025) | E27: 0.2 | F27: 元/kWh | G27: 2024 CNY | H27: 2024 | I27: 5% | J27: 折现率 (real/nom unstated — qc) | K27: 1,200 h | L27: n/p | M27: ≈3,450 元/kW | N27: — | O27: — | P27: N | R27: =E27*1000/fx_deflator!$D$9*fx_deflator!$F$9 | S27: 水电水利规划设计总院, 中国可再生能源工程造价管理报告2024年度 — primary PDF not retrievable; verified via 2 independent reproductions (CPEM 29.05.2025; 光伏們/Sina 28.05.2025) — retr. 2026-07-14. Flag qc Q13.
A28: CN | B28: Onshore wind | C28: CREEI 造价报告 2024 | E28: 0.18 | F28: 元/kWh | G28: 2024 CNY | H28: 2024 | I28: 5% | J28: as above | K28: 2,000 h | L28: n/p | M28: ≈4,200 元/kW | N28: — | O28: — | P28: N | R28: =E28*1000/fx_deflator!$D$9*fx_deflator!$F$9 | S28: As above.
A29: CN | B29: Offshore wind | C29: CREEI 造价报告 2024 | D29: 0.25 | E29: 0.33 | F29: 元/kWh | G29: 2024 CNY | H29: 2024 | I29: 5% | J29: as above | K29: 2,800 h | L29: n/p | M29: 9,000–12,500 元/kW (typ. 9,680) | N29: — | O29: — | P29: N | Q29: =D29*1000/fx_deflator!$D$9*fx_deflator!$F$9 | R29: =E29*1000/fx_deflator!$D$9*fx_deflator!$F$9 | S29: As above.
A30: CN | B30: Solar PV / onshore / offshore | C30: IRENA RPGC 2024 (Jul 2025) — cross-check | F30: USD/kWh | G30: 2024 USD | H30: 2024 | I30: ≈5% real after-tax (default) | J30: IRENA benchmark | K30: offshore CF 37% | L30: 25 | M30: offshore TIC $1,520/kW | N30: — | O30: — | P30: N | S30: IRENA, Renewable Power Generation Costs in 2024, pp.13–18/31/43–46: PV $0.033, onshore $0.029, offshore $0.056/kWh — retr. 2026-07-14. Cross-check only; converted rows below use WEO/CREEI.
A31: CN | B31: Coal / CCGT / nuclear @7% real | C31: IEA/NEA EGC 2020 (published harmonised) | F31: USD/MWh | G31: 2018 USD | H31: 2025 comm. | I31: 7% real | J31: standardised | K31: 85% CF | L31: 40/30/60 | M31: $800/560/2500 per kW | N31: coal $88/t 6000kcal; gas $9.1/MBtu | O31: $30/tCO2 harmonised | P31: N | S31: IEA/NEA, Projected Costs of Generating Electricity 2020, Tables 3.11a/3.12/3.13a — coal 74.66, CCGT 84.00, nuclear 66.01 USD/MWh @7% — retr. 2026-07-14. 2020 vintage: pre-dates 2021–24 Chinese capex declines. Converted in section 2.
A32: CN | B32: OCGT | C32: — | P32: GAP | S32: NO source anywhere (incl. EGC 2020 — China submitted no OCGT). Complete gap; a finding.
A33: UK | B33: Nuclear — Hinkley Point C CfD price (NOT an LCOE) | C33: NAO, Sizewell C (HC 33), 20.05.2026, para 2.19 | E33: 128.94 | F33: £/MWh | G33: 2025 prices | H33: contract, 35 yrs from operation | I33: n/a | J33: negotiated price embedding EDF return | K33: n/a | L33: 35 (contract) | M33: £31-35bn build (NAO 2023 range) | N33: in price | O33: in price | P33: N | R33: 170.1 | S33: NAO Sizewell C 2026 p.44: HPC CfD = GBP 128.94/MWh in 2025 prices, on the GBP 89.50 (2012-price) basis — the GBP 3 reduction from 92.50 TRIGGERED at the SZC FID of 22.07.2025 (NAO para 1.14). Contractual indexation: CPI D7BT, base Oct-2011 = 94.5, reset each 1 April on January CPI (LCCC SPA Guidance Feb 2026 v7): 2025/26 season 89.50 x 135.4/94.5 = 128.24; 2026/27 = 132.12. A negotiated PRICE embedding the developer return, not an LCOE (NAO 2017: consumers locked into a risky and expensive project). USD = x1.3192 (2025 avg). S200.
A34: DE | B34: Nuclear — restart of closed fleet | C34: Radiant Energy Group, Restarting Germany’s Reactors: Viability and Outlook, Jun 2026, pp.15-19 | D34: 37 | E34: 71 | F34: EUR/MWh | G34: 2026 prices | H34: 2026 | I34: 4.25% (state) / 7.38% (private) | J34: WACC scenarios II / I | K34: 147 TWh/yr fleet | L34: 20-yr repayment | M34: EUR 1.0-4.8bn/unit; program EUR 39.3bn | N34: industry-expert opex/fuel | O34: EUR 4/MWh waste/decom | P34: Y | Q34: 41.83 | R34: 80.27 | S34: 14 restartable reactors, 18.7 GW, in 3 priority groups; group LCOE means: state-backed (Scen II) A/B EUR 37, C 58; private (Scen I) A 41 / B 42 / C 71; cheapest unit Brokdorf 31-33. Range entered = 37 (Scen II A/B) to 71 (Scen I C). CAVEATS: restart-advocacy-adjacent source, anonymous industry opex sourcing, not peer-reviewed; 35% baseline overrun adder +/-20% is in the numbers. Nearest independent anchor: IEA/NEA EGC 2020 Table 8.1 LTO (lifetime extension) USD 26.4-48.5/MWh, central 31-36 at 7%/85%CF (S200). USD = x1.1306 (2025 avg; 2026 annual FX does not exist yet per D6 — deviation immaterial vs the model’s own overrun band). estimated=Y.
A35: 2. HARMONISED-WACC VARIANT — ALL MODELLED (estimated=Y). Method (decision D15): capital component = capex × CRF(WACC, life) ÷ annual generation per kW; residual = published LCOE − capital component (holds fuel, carbon, O&M); harmonised LCOE = capital at common WACC + residual. Common rate:
A36: Common real WACC (editable input; user-approved 2026-07-14): | D36: 0.07
A37: Ctry | B37: Tech / case | C37: Basis | D37: Capex total (loc/kW) | E37: Gen (MWh/kW·yr) | F37: Life (y) | G37: Native WACC | H37: CRF native | I37: CRF common | J37: Capital native (/MWh) | K37: Published LCOE (loc/MWh) | L37: Residual | M37: Resid. chk | N37: Harmonised (loc/MWh) | O37: est? | P37: Real25 USD/MWh | R37: Notes
A38: UK | B38: CCGT H-class | C38: DESNZ 2023 inputs | D38: 624.42 | E38: 8.1468 | F38: 25 | G38: 0.075 | H38: =G38*(1+G38)^F38/((1+G38)^F38-1) | I38: =$D$36*(1+$D$36)^F38/((1+$D$36)^F38-1) | J38: =D38*H38/E38 | K38: 114 | L38: =K38-J38 | M38: =IF(L38<0,"NEG-flag","ok") | N38: =D38*I38/E38+L38 | O38: Y | P38: =N38*fx_deflator!$B$6*fx_deflator!$F$6 | R38: Capex £610/kW + infra £17.3m/1200MW. Gen = 8.76×93%.
A39: UK | B39: OCGT 300MW 2000h | C39: DESNZ 2023 inputs | D39: 579.78 | E39: 1.9272 | F39: 25 | G39: 0.071 | H39: =G39*(1+G39)^F39/((1+G39)^F39-1) | I39: =$D$36*(1+$D$36)^F39/((1+$D$36)^F39-1) | J39: =D39*H39/E39 | K39: 197 | L39: =K39-J39 | M39: =IF(L39<0,"NEG-flag","ok") | N39: =D39*I39/E39+L39 | O39: Y | P39: =N39*fx_deflator!$B$6*fx_deflator!$F$6 | R39: £530/kW + £15.5m/311.36MW; 8.76×22%.
A40: UK | B40: Onshore wind | C40: DESNZ 2023 inputs | D40: 1304.07 | E40: 3.942 | F40: 25 | G40: 0.052 | H40: =G40*(1+G40)^F40/((1+G40)^F40-1) | I40: =$D$36*(1+$D$36)^F40/((1+$D$36)^F40-1) | J40: =D40*H40/E40 | K40: 38 | L40: =K40-J40 | M40: =IF(L40<0,"NEG-flag","ok") | N40: =D40*I40/E40+L40 | O40: Y | P40: =N40*fx_deflator!$B$6*fx_deflator!$F$6 | R40: £1,230/kW + £3.8m/51.3MW; 8.76×45%.
A41: UK | B41: Offshore wind | C41: DESNZ 2023 inputs | D41: 1694.3 | E41: 5.3436 | F41: 30 | G41: 0.063 | H41: =G41*(1+G41)^F41/((1+G41)^F41-1) | I41: =$D$36*(1+$D$36)^F41/((1+$D$36)^F41-1) | J41: =D41*H41/E41 | K41: 44 | L41: =K41-J41 | M41: =IF(L41<0,"NEG-flag","ok") | N41: =D41*I41/E41+L41 | O41: Y | P41: =N41*fx_deflator!$B$6*fx_deflator!$F$6 | R41: £1,630/kW + £64.3m/1000MW; 8.76×61%.
...

Sheet cn_td
A1: CHINA T&D PRICES (输配电价) — 工商业 两部制, seven basket provinces. 3rd period (526号, eff. 01.06.2023) and 4th period (1077号, eff. 01.08.2026). Retrieved 2026-07-14 from primary NDRC annex PDFs.
A2: Native units: 电量电价 元/千瓦时; 需量电价 元/千瓦·月; 容量电价 元/千伏安·月. Prices incl. VAT & base-period cross-subsidy; excl. 政府性基金及附加, line loss (per-province 上网环节线损率 noted), system operation fees. Calendar-2026 series = 7/12 × 3rd + 5/12 × 4th (D13-R).
A4: Province | B4: P3 220kV 电量 | C4: P3 220kV 需量 | D4: P4 220kV 电量 | E4: P4 220kV 需量 | F4: P3 10kV 电量 | G4: P4 10kV 电量 | H4: Notes (P3/P4 capacity variants; line-loss rates; source pages)
A5: Jiangsu 江苏 | B5: 0.0597 | C5: 41.6 | D5: 0.0518 | E5: 41.6 | F5: 0.1357 | G5: 0.1298 | H5: 容量: P3/P4 26.0 (220kV), 32.0 (10kV). 需量 10kV: 51.2/51.2. 线损率: P3 3.18% → P4 省内 2.83%. P4 annex p.12.
A6: Guangdong 广东 | B6: 0.0457 | C6: 26.1 | D6: 0.0449 | E6: 26.1 | F6: 0.0985 | G6: 0.0979 | H6: P4: 35~110kV merged class; 容量 16.3 (220kV), 22.6 (10kV); 需量 10kV 36.1; 省内线损率 3.31%; ex-Shenzhen average; annex p.21. P3 extracted 2026-07-15 (annex pp. per page index).
A7: Shandong 山东 | B7: 0.1041 | C7: 32 | D7: 0.089 | E7: 32 | F7: 0.1491 | G7: 0.14 | H7: P4: 容量 20.0/25.0; 需量 10kV 40.0; 线损率 3.07%; annex p.17. P3 extracted 2026-07-15.
A8: Zhejiang 浙江 | B8: 0.0688 | C8: 38.3 | D8: 0.0663 | E8: 37.6 | F8: 0.126 | G8: 0.125 | H8: P4: 容量 23.5/29.5; 需量 10kV 47.2; annex p.13. P3 extracted 2026-07-15.
A9: Henan 河南 | B9: 0.103 | C9: 30.5 | D9: 0.098 | E9: 30.4 | F9: 0.168 | G9: 0.1655 | H9: P4: 容量 19.0/25.0; 需量 10kV 40.0; 省内线损率 4.82%; annex p.18. P3 extracted 2026-07-15.
A10: Inner Mongolia 蒙西 | B10: 0.0455 | C10: 31.2 | D10: 0.0429 | E10: 31.2 | F10: 0.0795 | G10: 0.0787 | H10: P4: 容量 19.5/21.5; 需量 10kV 34.4; 线损率 2.81%; uniquely has <1kV two-part class; annex p.7. Basket uses 蒙西 (west grid) — 蒙东 not extracted (decision-log if needed). P3 extracted 2026-07-15.
A11: Sichuan 四川 | B11: 0.0478 | C11: 24 | D11: 0.0466 | E11: 24 | F11: 0.139 | G11: 0.1391 | H11: P4: 容量 15.0/22.0; 需量 10kV 35.0; 省内线损率 5.64%; extensive hydro-export notes; annex p.26. P3 extracted 2026-07-15.
A13: Sources: 发改价格〔2023〕526号 annex (P020230515609052875117.pdf); 发改价格〔2026〕1077号 annex 1 (P020260710613207914509.pdf) — both ndrc.gov.cn, retrieved 2026-07-14. P4 structural changes: new 单一制 110/220kV classes; standardised 0.03 元/kWh inter-provincial mutual-aid export price; pumped-storage/gas capacity-fee notes removed from tables (系统运行费 definition sits in 发改价格规〔2025〕1490号 — not yet retrieved, qc).
A14: P3 values for GD/SD/ZJ/HN/蒙西/SC extracted 2026-07-15 from 526号 annex PDF (in-session re-download, pdfplumber): 两部制 rows, pages 蒙西 p.7, 浙江 p.13, 山东 p.17, 河南 p.18, 广东 p.21, 四川 p.26 (0-indexed). Cross-checks: SD 10kV 0.1491 = SD Oct-2025 bill 输配 0.1491 ✓; HN 10kV 0.1680 = HN May-2025 bill 输配 0.168 ✓. P3 10kV 需量 in stage4_cn.

Sheet timeseries
A1: ALL-IN PRICE TIME SERIES — stage 4 build (2026-07-15). Both archetypes × E1/E2 × 3 countries, 2010–2026 (D19). Formula-driven from stage4_uk / stage4_de / stage4_cn / cn_td / assumptions. Nominal local currency per MWh; real 2025 USD/MWh block below (no 2026 conversion, D6). E1/E2 are MODELLED, not observed. Build-up EXCLUDES supply cost & margin (function 6) — noted at the validation gate. Blank cell = source gap (anti-fabrication) — see completeness rows.
A2: Structural breaks to mark on every chart — UK: CfD-ILR 2016 · EII exemptions 2018 → 100% 04/2024 · TCR DUoS 04/2022, TNUoS bands + BSUoS reform 04/2023 · NCC 04/2025 (backdated 04/2024), 90% 04/2026 · wholesale = day-ahead PROXY pre-2022 (D22). DE: §19 floors 2014 (2011–13 exemption era not modelled — gap) · Offshore/SPK 2013 · BesAR-2014 redesign · KWKG/Offshore privileged rates company-specific 2017/2019 (E2=E1, D25) · DE-AT split 10/2018 · EEG→0 07/2022, budget 2023 · ÜNB harmonisation 2023 · €6.5bn subsidy 2026 (incidence iii). CN: renormalised basket, coverage row shown (D23) · 2021-10 catalogue end (2021 = Jan–Sep basis) · 代理购电 12/2021 · 526号 06/2023 · 容量电价 2024 · 136号文 06/2025 · 1077号 08/2026 (month-weighted, D13-R). CN E1=E2 (no formal exemption regime — functional equivalents owned in text).
A4: Ctry | B4: Series / component | C4: Case | D4: 2010 | E4: 2011 | F4: 2012 | G4: 2013 | H4: 2014 | I4: 2015 | J4: 2016 | K4: 2017 | L4: 2018 | M4: 2019 | N4: 2020 | O4: 2021 | P4: 2022 | Q4: 2023 | R4: 2024 | S4: 2025 | T4: 2026 | U4: Method / source note
A5: UK — LARGE archetype (500 GWh, 8,000h, transmission-connected, Humber zone 5). Nominal £/MWh.
A6: UK | B6: Wholesale (rolling year-ahead; day-ahead PROXY ≤2021, D22) | C6: E1+E2 | D6: =stage4_uk!D9 | E6: =stage4_uk!E9 | F6: =stage4_uk!F9 | G6: =stage4_uk!G9 | H6: =stage4_uk!H9 | I6: =stage4_uk!I9 | J6: =stage4_uk!J9 | K6: =stage4_uk!K9 | ... T6: =stage4_uk!T9 | U6: stage4_uk. estimated=Y (annualised); 2010 DA Jun–Dec; 2026 partial obs-yr.
A7: UK | B7: TNUoS (triad-era £/kW × 1000/h; TCR residual T-Demand4 ×365/MWh from 2023) | C7: per arch. | D7: =stage4_uk!D25*1000/assumptions!$B$7 | E7: =stage4_uk!E25*1000/assumptions!$B$7 | F7: =stage4_uk!F25*1000/assumptions!$B$7 | G7: =stage4_uk!G25*1000/assumptions!$B$7 | H7: =stage4_uk!H25*1000/assumptions!$B$7 | I7: =stage4_uk!I25*1000/assumptions!$B$7 | J7: =stage4_uk!J25*1000/assumptions!$B$7 | K7: =stage4_uk!K25*1000/assumptions!$B$7 | ... P7: =stage4_uk!P25*1000/assumptions!$B$7 | Q7: =stage4_uk!Q26*365/assumptions!$B$6 | R7: =stage4_uk!R26*365/assumptions!$B$6 | S7: =stage4_uk!S26*365/assumptions!$B$6 | T7: =stage4_uk!T26*365/assumptions!$B$6 | U7: Flat-baseload: triad demand = avg demand (est=Y). Zone-5 locational zero-floored throughout.
A8: UK | B8: BSUoS (outturn unweighted avg 2010–22, own comp. from NESO HH RF; FT primary-verified 2023+) | C8: E1+E2 | D8: =stage4_uk!D30 | E8: =stage4_uk!E30 | F8: =stage4_uk!F30 | G8: =stage4_uk!G30 | H8: =stage4_uk!H30 | I8: =stage4_uk!I30 | J8: =stage4_uk!J30 | K8: =stage4_uk!K30 | ... T8: =stage4_uk!T30 | U8: Demand-only from 04/2023 (CMP308/361).
A9: UK | B9: AAHEDC (2010/11–2020/21 from NG final tariff letters; Shetland step 2021/22 flagged) | C9: E1+E2 | D9: =stage4_uk!D31*10 | E9: =stage4_uk!E31*10 | F9: =stage4_uk!F31*10 | G9: =stage4_uk!G31*10 | H9: =stage4_uk!H31*10 | I9: =stage4_uk!I31*10 | J9: =stage4_uk!J31*10 | K9: =stage4_uk!K31*10 | ... T9: =stage4_uk!T31*10 | U9: p/kWh × 10. Excluded from NCC base (unverified — conservative).
A10: UK | B10: RO (buy-out × obligation) | C10: E1 | D10: =stage4_uk!D14 | E10: =stage4_uk!E14 | F10: =stage4_uk!F14 | G10: =stage4_uk!G14 | H10: =stage4_uk!H14 | I10: =stage4_uk!I14 | J10: =stage4_uk!J14 | K10: =stage4_uk!K14 | ... T10: =stage4_uk!T14 | U10: estimated=Y (ignores recycle value).
A11: UK | B11: CfD ILR annual avg (scheme from 2016; 2015/16 GAP) | C11: E1 | J11: =stage4_uk!J19 | K11: =stage4_uk!K19 | L11: =stage4_uk!L19 | M11: =stage4_uk!M19 | N11: =stage4_uk!N19 | O11: =stage4_uk!O19 | P11: =stage4_uk!P19 | Q11: =stage4_uk!Q19 | ... T11: =stage4_uk!T19
A12: UK | B12: FiT levelisation (2010–14 D27 est.; SY16/2025 unpublished — blank) | C12: E1 | D12: =stage4_uk!D20 | E12: =stage4_uk!E20 | F12: =stage4_uk!F20 | G12: =stage4_uk!G20 | H12: =stage4_uk!H20 | I12: =stage4_uk!I20 | J12: =stage4_uk!J20 | K12: =stage4_uk!K20 | ... R12: =stage4_uk!R20 | U12: Ofgem levelisation notices located.
A13: UK | B13: Capacity Market (derived per-MWh, D30; 2023 pre-final; scheme from 2016/17) | C13: E1 | K13: =stage4_uk!K21 | L13: =stage4_uk!L21 | M13: =stage4_uk!M21 | N13: =stage4_uk!N21 | O13: =stage4_uk!O21 | P13: =stage4_uk!P21 | Q13: =stage4_uk!Q21 | R13: =stage4_uk!R21 | ... T13: =stage4_uk!T21 | U13: EMRS Key Payment Figures located. Suspension 11/2018–10/2019.
A14: UK | B14: CCL (main rate) — E1 only. E2 carries ZERO (min/met exemption, D71). Band-average CCL actually paid is measured in r132/r133, not assumed. | C14: E1+E2 | D14: =stage4_uk!D22*10 | E14: =stage4_uk!E22*10 | F14: =stage4_uk!F22*10 | G14: =stage4_uk!G22*10 | H14: =stage4_uk!H22*10 | I14: =stage4_uk!I22*10 | J14: =stage4_uk!J22*10 | K14: =stage4_uk!K22*10 | ... T14: =stage4_uk!T22*10
A15: UK | B15: E1 TOTAL (statutory, excl supply margin; incl ESL 2025+ via stage4_uk r53; completeness row below) | C15: E1 | D15: =SUM(D6:D14)+IF(ISNUMBER(stage4_uk!D53),stage4_uk!D53,0)+IF(ISNUMBER(D107),D107,0) | E15: =SUM(E6:E14)+IF(ISNUMBER(stage4_uk!E53),stage4_uk!E53,0)+IF(ISNUMBER(E107),E107,0) | F15: =SUM(F6:F14)+IF(ISNUMBER(stage4_uk!F53),stage4_uk!F53,0)+IF(ISNUMBER(F107),F107,0) | G15: =SUM(G6:G14)+IF(ISNUMBER(stage4_uk!G53),stage4_uk!G53,0)+IF(ISNUMBER(G107),G107,0) | H15: =SUM(H6:H14)+IF(ISNUMBER(stage4_uk!H53),stage4_uk!H53,0)+IF(ISNUMBER(H107),H107,0) | I15: =SUM(I6:I14)+IF(ISNUMBER(stage4_uk!I53),stage4_uk!I53,0)+IF(ISNUMBER(I107),I107,0) | J15: =SUM(J6:J14)+IF(ISNUMBER(stage4_uk!J53),stage4_uk!J53,0)+IF(ISNUMBER(J107),J107,0) | K15: =SUM(K6:K14)+IF(ISNUMBER(stage4_uk!K53),stage4_uk!K53,0)+IF(ISNUMBER(K107),K107,0) | ... T15: =SUM(T6:T14)+IF(ISNUMBER(stage4_uk!T53),stage4_uk!T53,0)+IF(ISNUMBER(T107),T107,0) | U15: MODELLED.
A16: UK | B16: E1/E2 completeness (missing retrieved components) | C16: note | D16: complete (FiT D27 est.; DUoS recon. D28 [medium]; CM n/a) | E16: complete (FiT D27 est.; DUoS recon.; CM n/a) | F16: complete (FiT D27 est.; DUoS retrieved; CM n/a) | G16: complete (FiT D27 est.; DUoS recon.; CM n/a) | H16: complete (FiT D27 est.; DUoS recon.; CM n/a) | I16: complete (CM n/a) | J16: complete (CM n/a) | K16: complete (CM TA est.) | L16: complete | M16: complete | N16: complete | O16: complete | P16: complete | Q16: complete (CM pre-final total — final unpublished) | R16: complete | S16: excl FiT 2025/26 (unpublished ~7 £/MWh); ESL est. | T16: excl FiT; CM in-year; ESL est.; wholesale part-yr | U16: Understates totals where components missing — gate provisional pre-2024.
A17: UK | B17: E2 network = (TNUoS+BSUoS)×(1−NCC share) + AAHEDC | C17: E2 | D17: =(D7+SUM(D8))*(1-IF(ISNUMBER(stage4_uk!D48),stage4_uk!D48,0))+SUM(D9) | E17: =(E7+SUM(E8))*(1-IF(ISNUMBER(stage4_uk!E48),stage4_uk!E48,0))+SUM(E9) | F17: =(F7+SUM(F8))*(1-IF(ISNUMBER(stage4_uk!F48),stage4_uk!F48,0))+SUM(F9) | G17: =(G7+SUM(G8))*(1-IF(ISNUMBER(stage4_uk!G48),stage4_uk!G48,0))+SUM(G9) | H17: =(H7+SUM(H8))*(1-IF(ISNUMBER(stage4_uk!H48),stage4_uk!H48,0))+SUM(H9) | I17: =(I7+SUM(I8))*(1-IF(ISNUMBER(stage4_uk!I48),stage4_uk!I48,0))+SUM(I9) | J17: =(J7+SUM(J8))*(1-IF(ISNUMBER(stage4_uk!J48),stage4_uk!J48,0))+SUM(J9) | K17: =(K7+SUM(K8))*(1-IF(ISNUMBER(stage4_uk!K48),stage4_uk!K48,0))+SUM(K9) | ... T17: =(T7+SUM(T8))*(1-IF(ISNUMBER(stage4_uk!T48),stage4_uk!T48,0))+SUM(T9) | U17: NCC 60% 2024–25, 90% 2026 (SI 2026/243); recovered via ESL — incidence (ii).
A18: UK | B18: E2 levies = RO/CfD/FiT/CM after exemption shares (FiT+CM now live) | C18: E2 | D18: =SUM(D10)*(1-IF(ISNUMBER(stage4_uk!D45),stage4_uk!D45,0))+SUM(D11)*(1-IF(ISNUMBER(stage4_uk!D44),stage4_uk!D44,0))+SUM(D12)*(1-IF(ISNUMBER(stage4_uk!D46),stage4_uk!D46,0))+SUM(D13)*(1-IF(ISNUMBER(stage4_uk!D47),stage4_uk!D47,0)) | E18: =SUM(E10)*(1-IF(ISNUMBER(stage4_uk!E45),stage4_uk!E45,0))+SUM(E11)*(1-IF(ISNUMBER(stage4_uk!E44),stage4_uk!E44,0))+SUM(E12)*(1-IF(ISNUMBER(stage4_uk!E46),stage4_uk!E46,0))+SUM(E13)*(1-IF(ISNUMBER(stage4_uk!E47),stage4_uk!E47,0)) | F18: =SUM(F10)*(1-IF(ISNUMBER(stage4_uk!F45),stage4_uk!F45,0))+SUM(F11)*(1-IF(ISNUMBER(stage4_uk!F44),stage4_uk!F44,0))+SUM(F12)*(1-IF(ISNUMBER(stage4_uk!F46),stage4_uk!F46,0))+SUM(F13)*(1-IF(ISNUMBER(stage4_uk!F47),stage4_uk!F47,0)) | G18: =SUM(G10)*(1-IF(ISNUMBER(stage4_uk!G45),stage4_uk!G45,0))+SUM(G11)*(1-IF(ISNUMBER(stage4_uk!G44),stage4_uk!G44,0))+SUM(G12)*(1-IF(ISNUMBER(stage4_uk!G46),stage4_uk!G46,0))+SUM(G13)*(1-IF(ISNUMBER(stage4_uk!G47),stage4_uk!G47,0)) | H18: =SUM(H10)*(1-IF(ISNUMBER(stage4_uk!H45),stage4_uk!H45,0))+SUM(H11)*(1-IF(ISNUMBER(stage4_uk!H44),stage4_uk!H44,0))+SUM(H12)*(1-IF(ISNUMBER(stage4_uk!H46),stage4_uk!H46,0))+SUM(H13)*(1-IF(ISNUMBER(stage4_uk!H47),stage4_uk!H47,0)) | I18: =SUM(I10)*(1-IF(ISNUMBER(stage4_uk!I45),stage4_uk!I45,0))+SUM(I11)*(1-IF(ISNUMBER(stage4_uk!I44),stage4_uk!I44,0))+SUM(I12)*(1-IF(ISNUMBER(stage4_uk!I46),stage4_uk!I46,0))+SUM(I13)*(1-IF(ISNUMBER(stage4_uk!I47),stage4_uk!I47,0)) | J18: =SUM(J10)*(1-IF(ISNUMBER(stage4_uk!J45),stage4_uk!J45,0))+SUM(J11)*(1-IF(ISNUMBER(stage4_uk!J44),stage4_uk!J44,0))+SUM(J12)*(1-IF(ISNUMBER(stage4_uk!J46),stage4_uk!J46,0))+SUM(J13)*(1-IF(ISNUMBER(stage4_uk!J47),stage4_uk!J47,0)) | K18: =SUM(K10)*(1-IF(ISNUMBER(stage4_uk!K45),stage4_uk!K45,0))+SUM(K11)*(1-IF(ISNUMBER(stage4_uk!K44),stage4_uk!K44,0))+SUM(K12)*(1-IF(ISNUMBER(stage4_uk!K46),stage4_uk!K46,0))+SUM(K13)*(1-IF(ISNUMBER(stage4_uk!K47),stage4_uk!K47,0)) | ... T18: =SUM(T10)*(1-IF(ISNUMBER(stage4_uk!T45),stage4_uk!T45,0))+SUM(T11)*(1-IF(ISNUMBER(stage4_uk!T44),stage4_uk!T44,0))+SUM(T12)*(1-IF(ISNUMBER(stage4_uk!T46),stage4_uk!T46,0))+SUM(T13)*(1-IF(ISNUMBER(stage4_uk!T47),stage4_uk!T47,0)) | U18: 85% era 2016/2018 → 100% 04/2024. FiT/CM terms absent (series GAP).
A19: UK | B19: E2 TOTAL (relieved EII; assumes full qualification) — CCL = 0 from D71 2026-07-26: mineralogical and metallurgical processes are EXEMPT from the CCL main rates (HMRC Notice CCL1/3 s3.14 + Annex A, from 01.04.2014), which covers the steel / aluminium / cement archetypes. A non-min/met EII (e.g. paper) would instead pay 8% of the main rate under a CCA — flagged, not modelled. | C19: E2 | D19: =D6+D17+D18+IF(ISNUMBER(D108),D108,0) | E19: =E6+E17+E18+IF(ISNUMBER(E108),E108,0) | F19: =F6+F17+F18+IF(ISNUMBER(F108),F108,0) | G19: =G6+G17+G18+IF(ISNUMBER(G108),G108,0) | H19: =H6+H17+H18+IF(ISNUMBER(H108),H108,0) | I19: =I6+I17+I18+IF(ISNUMBER(I108),I108,0) | J19: =J6+J17+J18+IF(ISNUMBER(J108),J108,0) | K19: =K6+K17+K18+IF(ISNUMBER(K108),K108,0) | ... T19: =T6+T17+T18+IF(ISNUMBER(T108),T108,0) | U19: MODELLED. Same completeness caveats as E1.
A20: UK | B20: OBSERVED: QEP Extra Large band, INCL CCL (D71; validation only) | C20: obs | D20: =stage4_uk!D51*10 | E20: =stage4_uk!E51*10 | F20: =stage4_uk!F51*10 | G20: =stage4_uk!G51*10 | H20: =stage4_uk!H51*10 | I20: =stage4_uk!I51*10 | J20: =stage4_uk!J51*10 | K20: =stage4_uk!K51*10 | ... S20: =stage4_uk!S51*10 | U20: DESNZ QEP 3.4.1 annual. Fully delivered incl margin, EXCL CCL.
A21: UK — MEDIUM archetype (20 GWh, 5,000h, HV distribution, NPg Yorkshire). Nominal £/MWh.
A22: UK | B22: Wholesale (as large) | C22: E1+E2 | D22: =stage4_uk!D9 | E22: =stage4_uk!E9 | F22: =stage4_uk!F9 | G22: =stage4_uk!G9 | H22: =stage4_uk!H9 | I22: =stage4_uk!I9 | J22: =stage4_uk!J9 | K22: =stage4_uk!K9 | ... T22: =stage4_uk!T9
A23: UK | B23: TNUoS medium (triad-era £/kW ×1000/h; HV4 residual ×365/MWh from 2023) | C23: per arch. | D23: =stage4_uk!D25*1000/assumptions!$C$7 | E23: =stage4_uk!E25*1000/assumptions!$C$7 | F23: =stage4_uk!F25*1000/assumptions!$C$7 | G23: =stage4_uk!G25*1000/assumptions!$C$7 | H23: =stage4_uk!H25*1000/assumptions!$C$7 | I23: =stage4_uk!I25*1000/assumptions!$C$7 | J23: =stage4_uk!J25*1000/assumptions!$C$7 | K23: =stage4_uk!K25*1000/assumptions!$C$7 | ... P23: =stage4_uk!P25*1000/assumptions!$C$7 | Q23: =stage4_uk!Q27*365/assumptions!$C$6 | R23: =stage4_uk!R27*365/assumptions!$C$6 | S23: =stage4_uk!S27*365/assumptions!$C$6 | T23: =stage4_uk!T27*365/assumptions!$C$6 | U23: Triad demand = avg operating demand 4 MW (est=Y — a 5,000h plant is assumed operating at triads; qc). HV4 band inferred (D12).
A24: UK | B24: DUoS unit rates (red/amber/green × band-hour shares; uniform-operation weighting, est=Y) | C24: medium | D24: =IF(ISNUMBER(stage4_uk!D34),(stage4_uk!D34*stage4_uk!$D$41+stage4_uk!D35*stage4_uk!$E$41+stage4_uk!D36*stage4_uk!$F$41)*10,"") | E24: =IF(ISNUMBER(stage4_uk!E34),(stage4_uk!E34*stage4_uk!$D$41+stage4_uk!E35*stage4_uk!$E$41+stage4_uk!E36*stage4_uk!$F$41)*10,"") | F24: =IF(ISNUMBER(stage4_uk!F34),(stage4_uk!F34*stage4_uk!$D$41+stage4_uk!F35*stage4_uk!$E$41+stage4_uk!F36*stage4_uk!$F$41)*10,"") | G24: =IF(ISNUMBER(stage4_uk!G34),(stage4_uk!G34*stage4_uk!$D$41+stage4_uk!G35*stage4_uk!$E$41+stage4_uk!G36*stage4_uk!$F$41)*10,"") | H24: =IF(ISNUMBER(stage4_uk!H34),(stage4_uk!H34*stage4_uk!$D$41+stage4_uk!H35*stage4_uk!$E$41+stage4_uk!H36*stage4_uk!$F$41)*10,"") | I24: =IF(ISNUMBER(stage4_uk!I34),(stage4_uk!I34*stage4_uk!$D$41+stage4_uk!I35*stage4_uk!$E$41+stage4_uk!I36*stage4_uk!$F$41)*10,"") | J24: =IF(ISNUMBER(stage4_uk!J34),(stage4_uk!J34*stage4_uk!$D$41+stage4_uk!J35*stage4_uk!$E$41+stage4_uk!J36*stage4_uk!$F$41)*10,"") | K24: =IF(ISNUMBER(stage4_uk!K34),(stage4_uk!K34*stage4_uk!$D$41+stage4_uk!K35*stage4_uk!$E$41+stage4_uk!K36*stage4_uk!$F$41)*10,"") | ... T24: =IF(ISNUMBER(stage4_uk!T34),(stage4_uk!T34*stage4_uk!$D$41+stage4_uk!T35*stage4_uk!$E$41+stage4_uk!T36*stage4_uk!$F$41)*10,"") | U24: 2017/18 band definitions differ (flag). GAP 2010–16.
A25: UK | B25: DUoS fixed (p/MPAN/day; TCR Band-4 residual from 2022) | C25: medium | D25: =IF(ISNUMBER(stage4_uk!D37),stage4_uk!D37*365/100/assumptions!$C$6,"") | E25: =IF(ISNUMBER(stage4_uk!E37),stage4_uk!E37*365/100/assumptions!$C$6,"") | F25: =IF(ISNUMBER(stage4_uk!F37),stage4_uk!F37*365/100/assumptions!$C$6,"") | G25: =IF(ISNUMBER(stage4_uk!G37),stage4_uk!G37*365/100/assumptions!$C$6,"") | H25: =IF(ISNUMBER(stage4_uk!H37),stage4_uk!H37*365/100/assumptions!$C$6,"") | I25: =IF(ISNUMBER(stage4_uk!I37),stage4_uk!I37*365/100/assumptions!$C$6,"") | J25: =IF(ISNUMBER(stage4_uk!J37),stage4_uk!J37*365/100/assumptions!$C$6,"") | K25: =IF(ISNUMBER(stage4_uk!K37),stage4_uk!K37*365/100/assumptions!$C$6,"") | ... T25: =IF(ISNUMBER(stage4_uk!T37),stage4_uk!T37*365/100/assumptions!$C$6,"")
A26: UK | B26: DUoS capacity (p/kVA/day × agreed kVA; kVA = avg MW × 1000, pf≈1 est=Y) | C26: medium | D26: =IF(ISNUMBER(stage4_uk!D38),stage4_uk!D38*assumptions!$C$8*1000*365/100/assumptions!$C$6,"") | E26: =IF(ISNUMBER(stage4_uk!E38),stage4_uk!E38*assumptions!$C$8*1000*365/100/assumptions!$C$6,"") | F26: =IF(ISNUMBER(stage4_uk!F38),stage4_uk!F38*assumptions!$C$8*1000*365/100/assumptions!$C$6,"") | G26: =IF(ISNUMBER(stage4_uk!G38),stage4_uk!G38*assumptions!$C$8*1000*365/100/assumptions!$C$6,"") | H26: =IF(ISNUMBER(stage4_uk!H38),stage4_uk!H38*assumptions!$C$8*1000*365/100/assumptions!$C$6,"") | I26: =IF(ISNUMBER(stage4_uk!I38),stage4_uk!I38*assumptions!$C$8*1000*365/100/assumptions!$C$6,"") | J26: =IF(ISNUMBER(stage4_uk!J38),stage4_uk!J38*assumptions!$C$8*1000*365/100/assumptions!$C$6,"") | K26: =IF(ISNUMBER(stage4_uk!K38),stage4_uk!K38*assumptions!$C$8*1000*365/100/assumptions!$C$6,"") | ... T26: =IF(ISNUMBER(stage4_uk!T38),stage4_uk!T38*assumptions!$C$8*1000*365/100/assumptions!$C$6,"") | U26: Reactive not modelled (pf≈1).
A27: UK | B27: BSUoS / AAHEDC / RO / CfD / FiT / CM / CCL / ESL (as large) | C27: E1 | D27: =SUM(D8)+SUM(D9)+D10+SUM(D11)+SUM(D12)+SUM(D13)+D14+IF(ISNUMBER(stage4_uk!D53),stage4_uk!D53,0) | E27: =SUM(E8)+SUM(E9)+E10+SUM(E11)+SUM(E12)+SUM(E13)+E14+IF(ISNUMBER(stage4_uk!E53),stage4_uk!E53,0) | F27: =SUM(F8)+SUM(F9)+F10+SUM(F11)+SUM(F12)+SUM(F13)+F14+IF(ISNUMBER(stage4_uk!F53),stage4_uk!F53,0) | G27: =SUM(G8)+SUM(G9)+G10+SUM(G11)+SUM(G12)+SUM(G13)+G14+IF(ISNUMBER(stage4_uk!G53),stage4_uk!G53,0) | H27: =SUM(H8)+SUM(H9)+H10+SUM(H11)+SUM(H12)+SUM(H13)+H14+IF(ISNUMBER(stage4_uk!H53),stage4_uk!H53,0) | I27: =SUM(I8)+SUM(I9)+I10+SUM(I11)+SUM(I12)+SUM(I13)+I14+IF(ISNUMBER(stage4_uk!I53),stage4_uk!I53,0) | J27: =SUM(J8)+SUM(J9)+J10+SUM(J11)+SUM(J12)+SUM(J13)+J14+IF(ISNUMBER(stage4_uk!J53),stage4_uk!J53,0) | K27: =SUM(K8)+SUM(K9)+K10+SUM(K11)+SUM(K12)+SUM(K13)+K14+IF(ISNUMBER(stage4_uk!K53),stage4_uk!K53,0) | ... T27: =SUM(T8)+SUM(T9)+T10+SUM(T11)+SUM(T12)+SUM(T13)+T14+IF(ISNUMBER(stage4_uk!T53),stage4_uk!T53,0) | U27: Volumetric charges identical per MWh.
